Workbook
Name \a: #REF!
Name \a: #REF!
Name \b: #REF!
Name \b: #REF!
Name \c: #REF!
Name \c: #REF!
Name \d: #REF!
Name \d: #REF!
Name \e: #REF!
Name \e: #REF!
Name \f: #REF!
Name \f: #REF!
Name a: #REF!
Name a: #REF!
Name Banco_dados_IM: #REF!
Name Banco_dados_IM: #REF!
Name dd: #REF!
Name GWP.CH4: [1]FE_HuellaChile_2017!$B$6
Name GWP.CO2: [1]FE_HuellaChile_2017!$B$5
Name GWP.N2O: [1]FE_HuellaChile_2017!$B$7
Name Impact_flag: #N/A
Name Index: #N/A
Name IndexArray: #N/A
Name j: #REF!
Name kcal.a.kJ: [1]FE_HuellaChile_2017!$B$8
Name LatestChange: #N/A
Name LatestPerson: #N/A
Name LatestVersion: #N/A
Name Macro_status: #N/A
Name ModelName: #N/A
Name ºººº: #REF!
Name ºººº: #REF!
Name PC_G: [1]FE_HuellaChile_2017!$B$13
Name PC_SyL: [1]FE_HuellaChile_2017!$B$12
Name Q: #REF!
Name Q: #REF!
Name Quality_flag: #N/A
Name Risk_flag: #N/A
Name s: #REF!
Name s: #REF!
Name SECR_Cars_MarketSegment_Column: #N/A
Name SECR_Cars_MarketSegment_RANGE: #N/A
Name SECR_Cars_MarketSegment_Row: #N/A
Name Status_Checking: #N/A
Name Status_Overall: #N/A
Name Status_Update: #N/A
Name t_Bioenergy: #N/A
Name t_Bioenergy_LY: #N/A
Name t_Business_travel_air: #N/A
Name t_Business_travel_air_LY: #N/A
Name t_Business_travel_land: #N/A
Name t_business_travel_land_LY: #N/A
Name t_Business_travel_sea: #N/A
Name t_business_travel_sea_LY: #N/A
Name t_Conversions: #N/A
Name t_Conversions_LY: #N/A
Name t_Delivery_vehicles: #N/A
Name t_Delivery_vehicles_LY: #N/A
Name t_Freighting_goods: #N/A
Name t_Freighting_goods_LY: #N/A

Sheet INICIO
B11: Versión N° | C11: 2
B12: Fecha de última actualización | C12: 46146
B13: Desarrollado por | C13: Nataly Moyano Pozo - Profesional Programa HuellaChile
B14: Revisado y aprobado por | C14: Arturo Espinosa Cáceres - Coordinador Programa HuellaChile
B17: Leyenda | C17: Descripción
B18: INICIO | C18: Descripción del documento.
B19: RESUMEN | C19: Hoja resumen que agrupa todos los factores de emisión del documento.
B20: CONTROL DE CAMBIOS | C20: Contiene el seguimiento de los cambios realizados entre versiones del documento.
B21: 1.1 Combustión estacionaria | C21: Factores de emisión para combustión estacionaria. Utiliza de base las hojas: 1.1 V2 CH2 T2.4 y 1.1 y 1.2CUADROA1 - BNE 2024
B22: 1.1 V2 CH2 T2.4 | C22: Tabla proveniente de IPCC 2006 (vol2; chapter 2) , Table 2.4. Proporciona factores de emisión por defecto para la combustión estacionaria en la categoría Comercial/Institucional.
B23: 1.2 Combustión móvil | C23: Factores de emisión para combustión móvil. Utiliza de base las hojas: 1.2 V2 CH3 T3.2.1, 1.2 V2 CH3 T3.2.2 y 1.1 y 1.2CUADROA1 - BNE 2024
B24: 1.2 V2 CH3 T3.2.1 | C24: Tabla proveniente de IPCC 2006 (vol2; chapter 3) , Table 3.2.1. Proporciona factores de emisión de CO2 poe defecto del transporte terrestre y ragos de incertidumbre.
B25: 1.2 V2 CH3 T3.2.2 | C25: Tabla proveniente de IPCC 2006 (vol2; chapter 3) , Table 3.2.2. Proporciona factores de emisión por defecto de N2O y CH4 del transporte terrestre y rangos de incertidumbre.
B26: 1.1 y 1.2CUADROA1 - BNE 2024 | C26: Tablas provenientes del Balance Nacional de Energía 2024. Proporciona densidades y poderes caloríficos de diversos productos.
... B58: 3.6 Waste disposal | C58: Hoja proveniente de DEFRA 2025. Proporciona factores de emisión para tratamiento y/o disposición de residuos.

Sheet RESUMEN
B8: Alcance | C8: Categoría | D8: Subcategoría | E8: Nombre | F8: Auxiliar | G8: Unidad del dato de actividad | H8: Factor de emisión | I8: Unidades del factor de emisión | J8: Fuente 1 | K8: Fuente 2 | L8: Fuente 3
B9: Emisiones directas | C9: 1.1 Combustión estacionaria | D9: Caldera/Generador/General | E9: Nafta | F9: - | G9: metros cúbicos | H9: {=_xlfn.XLOOKUP(E9&G9,'1.1 Combustión estacionaria'!$B$16:$B$48&'1.1 Combustión estacionaria'!$F$16:$F$48,'1.1 Combustión estacionaria'!$AB$16:$AB$48,"-")} -> 2361.0161 | I9: {=_xlfn.XLOOKUP(E9&G9,'1.1 Combustión estacionaria'!$B$16:$B$48&'1.1 Combustión estacionaria'!$F$16:$F$48,'1.1 Combustión estacionaria'!$AC$16:$AC$48,"-")} -> kgCO2e/metros cúbicos | J9: {=_xlfn.XLOOKUP(E9&G9,'1.1 Combustión estacionaria'!$B$16:$B$48&'1.1 Combustión estacionaria'!$F$16:$F$48,'1.1 Combustión estacionaria'!$AD$16:$AD$48,"-")} -> IPCC 2006 (vol2; chapter 2) , Table 2.4 | K9: {=_xlfn.XLOOKUP(E9&G9,'1.1 Combustión estacionaria'!$B$16:$B$48&'1.1 Combustión estacionaria'!$F$16:$F$48,'1.1 Combustión estacionaria'!$AE$16:$AE$48,"-")} -> CNE BNE 2024 | L9: {=_xlfn.XLOOKUP(E9&G9,'1.1 Combustión estacionaria'!$B$16:$B$48&'1.1 Combustión estacionaria'!$F$16:$F$48,'1.1 Combustión estacionaria'!$AF$16:$AF$48,"-")} -> -
B10: Emisiones directas | C10: 1.1 Combustión estacionaria | D10: Caldera/Generador/General | E10: Nafta | F10: - | G10: litros | H10: {=_xlfn.XLOOKUP(E10&G10,'1.1 Combustión estacionaria'!$B$16:$B$48&'1.1 Combustión estacionaria'!$F$16:$F$48,'1.1 Combustión estacionaria'!$AB$16:$AB$48,"-")} -> 2.3610161 | I10: {=_xlfn.XLOOKUP(E10&G10,'1.1 Combustión estacionaria'!$B$16:$B$48&'1.1 Combustión estacionaria'!$F$16:$F$48,'1.1 Combustión estacionaria'!$AC$16:$AC$48,"-")} -> kgCO2e/litros | J10: {=_xlfn.XLOOKUP(E10&G10,'1.1 Combustión estacionaria'!$B$16:$B$48&'1.1 Combustión estacionaria'!$F$16:$F$48,'1.1 Combustión estacionaria'!$AD$16:$AD$48,"-")} -> IPCC 2006 (vol2; chapter 2) , Table 2.4 | K10: {=_xlfn.XLOOKUP(E10&G10,'1.1 Combustión estacionaria'!$B$16:$B$48&'1.1 Combustión estacionaria'!$F$16:$F$48,'1.1 Combustión estacionaria'!$AE$16:$AE$48,"-")} -> CNE BNE 2024 | L10: {=_xlfn.XLOOKUP(E10&G10,'1.1 Combustión estacionaria'!$B$16:$B$48&'1.1 Combustión estacionaria'!$F$16:$F$48,'1.1 Combustión estacionaria'!$AF$16:$AF$48,"-")} -> -
B11: Emisiones directas | C11: 1.1 Combustión estacionaria | D11: Caldera/Generador/General | E11: Carbón metalúrgico | F11: - | G11: toneladas | H11: {=_xlfn.XLOOKUP(E11&G11,'1.1 Combustión estacionaria'!$B$16:$B$48&'1.1 Combustión estacionaria'!$F$16:$F$48,'1.1 Combustión estacionaria'!$AB$16:$AB$48,"-")} -> 2652.7371 | I11: {=_xlfn.XLOOKUP(E11&G11,'1.1 Combustión estacionaria'!$B$16:$B$48&'1.1 Combustión estacionaria'!$F$16:$F$48,'1.1 Combustión estacionaria'!$AC$16:$AC$48,"-")} -> kgCO2e/toneladas | J11: {=_xlfn.XLOOKUP(E11&G11,'1.1 Combustión estacionaria'!$B$16:$B$48&'1.1 Combustión estacionaria'!$F$16:$F$48,'1.1 Combustión estacionaria'!$AD$16:$AD$48,"-")} -> IPCC 2006 (vol2; chapter 2) , Table 2.4 | K11: {=_xlfn.XLOOKUP(E11&G11,'1.1 Combustión estacionaria'!$B$16:$B$48&'1.1 Combustión estacionaria'!$F$16:$F$48,'1.1 Combustión estacionaria'!$AE$16:$AE$48,"-")} -> CNE BNE 2024 | L11: {=_xlfn.XLOOKUP(E11&G11,'1.1 Combustión estacionaria'!$B$16:$B$48&'1.1 Combustión estacionaria'!$F$16:$F$48,'1.1 Combustión estacionaria'!$AF$16:$AF$48,"-")} -> -
B12: Emisiones directas | C12: 1.1 Combustión estacionaria | D12: Caldera/Generador/General | E12: Carbón metalúrgico | F12: - | G12: kilogramos | H12: {=_xlfn.XLOOKUP(E12&G12,'1.1 Combustión estacionaria'!$B$16:$B$48&'1.1 Combustión estacionaria'!$F$16:$F$48,'1.1 Combustión estacionaria'!$AB$16:$AB$48,"-")} -> 2.6527371 | I12: {=_xlfn.XLOOKUP(E12&G12,'1.1 Combustión estacionaria'!$B$16:$B$48&'1.1 Combustión estacionaria'!$F$16:$F$48,'1.1 Combustión estacionaria'!$AC$16:$AC$48,"-")} -> kgCO2e/kilogramos | J12: {=_xlfn.XLOOKUP(E12&G12,'1.1 Combustión estacionaria'!$B$16:$B$48&'1.1 Combustión estacionaria'!$F$16:$F$48,'1.1 Combustión estacionaria'!$AD$16:$AD$48,"-")} -> IPCC 2006 (vol2; chapter 2) , Table 2.4 | K12: {=_xlfn.XLOOKUP(E12&G12,'1.1 Combustión estacionaria'!$B$16:$B$48&'1.1 Combustión estacionaria'!$F$16:$F$48,'1.1 Combustión estacionaria'!$AE$16:$AE$48,"-")} -> CNE BNE 2024 | L12: {=_xlfn.XLOOKUP(E12&G12,'1.1 Combustión estacionaria'!$B$16:$B$48&'1.1 Combustión estacionaria'!$F$16:$F$48,'1.1 Combustión estacionaria'!$AF$16:$AF$48,"-")} -> -
B13: Emisiones directas | C13: 1.1 Combustión estacionaria | D13: Caldera/Generador/General | E13: Carbón metalúrgico | F13: - | G13: gramos | H13: {=_xlfn.XLOOKUP(E13&G13,'1.1 Combustión estacionaria'!$B$16:$B$48&'1.1 Combustión estacionaria'!$F$16:$F$48,'1.1 Combustión estacionaria'!$AB$16:$AB$48,"-")} -> 0.0026527371 | I13: {=_xlfn.XLOOKUP(E13&G13,'1.1 Combustión estacionaria'!$B$16:$B$48&'1.1 Combustión estacionaria'!$F$16:$F$48,'1.1 Combustión estacionaria'!$AC$16:$AC$48,"-")} -> kgCO2e/gramos | J13: {=_xlfn.XLOOKUP(E13&G13,'1.1 Combustión estacionaria'!$B$16:$B$48&'1.1 Combustión estacionaria'!$F$16:$F$48,'1.1 Combustión estacionaria'!$AD$16:$AD$48,"-")} -> IPCC 2006 (vol2; chapter 2) , Table 2.4 | K13: {=_xlfn.XLOOKUP(E13&G13,'1.1 Combustión estacionaria'!$B$16:$B$48&'1.1 Combustión estacionaria'!$F$16:$F$48,'1.1 Combustión estacionaria'!$AE$16:$AE$48,"-")} -> CNE BNE 2024 | L13: {=_xlfn.XLOOKUP(E13&G13,'1.1 Combustión estacionaria'!$B$16:$B$48&'1.1 Combustión estacionaria'!$F$16:$F$48,'1.1 Combustión estacionaria'!$AF$16:$AF$48,"-")} -> -
B14: Emisiones directas | C14: 1.1 Combustión estacionaria | D14: Caldera/Generador/General | E14: Carbón térmico | F14: - | G14: toneladas | H14: {=_xlfn.XLOOKUP(E14&G14,'1.1 Combustión estacionaria'!$B$16:$B$48&'1.1 Combustión estacionaria'!$F$16:$F$48,'1.1 Combustión estacionaria'!$AB$16:$AB$48,"-")} -> 2652.7371 | I14: {=_xlfn.XLOOKUP(E14&G14,'1.1 Combustión estacionaria'!$B$16:$B$48&'1.1 Combustión estacionaria'!$F$16:$F$48,'1.1 Combustión estacionaria'!$AC$16:$AC$48,"-")} -> kgCO2e/toneladas | J14: {=_xlfn.XLOOKUP(E14&G14,'1.1 Combustión estacionaria'!$B$16:$B$48&'1.1 Combustión estacionaria'!$F$16:$F$48,'1.1 Combustión estacionaria'!$AD$16:$AD$48,"-")} -> IPCC 2006 (vol2; chapter 2) , Table 2.4 | K14: {=_xlfn.XLOOKUP(E14&G14,'1.1 Combustión estacionaria'!$B$16:$B$48&'1.1 Combustión estacionaria'!$F$16:$F$48,'1.1 Combustión estacionaria'!$AE$16:$AE$48,"-")} -> CNE BNE 2024 | L14: {=_xlfn.XLOOKUP(E14&G14,'1.1 Combustión estacionaria'!$B$16:$B$48&'1.1 Combustión estacionaria'!$F$16:$F$48,'1.1 Combustión estacionaria'!$AF$16:$AF$48,"-")} -> -
B15: Emisiones directas | C15: 1.1 Combustión estacionaria | D15: Caldera/Generador/General | E15: Carbón térmico | F15: - | G15: kilogramos | H15: {=_xlfn.XLOOKUP(E15&G15,'1.1 Combustión estacionaria'!$B$16:$B$48&'1.1 Combustión estacionaria'!$F$16:$F$48,'1.1 Combustión estacionaria'!$AB$16:$AB$48,"-")} -> 2.6527371 | I15: {=_xlfn.XLOOKUP(E15&G15,'1.1 Combustión estacionaria'!$B$16:$B$48&'1.1 Combustión estacionaria'!$F$16:$F$48,'1.1 Combustión estacionaria'!$AC$16:$AC$48,"-")} -> kgCO2e/kilogramos | J15: {=_xlfn.XLOOKUP(E15&G15,'1.1 Combustión estacionaria'!$B$16:$B$48&'1.1 Combustión estacionaria'!$F$16:$F$48,'1.1 Combustión estacionaria'!$AD$16:$AD$48,"-")} -> IPCC 2006 (vol2; chapter 2) , Table 2.4 | K15: {=_xlfn.XLOOKUP(E15&G15,'1.1 Combustión estacionaria'!$B$16:$B$48&'1.1 Combustión estacionaria'!$F$16:$F$48,'1.1 Combustión estacionaria'!$AE$16:$AE$48,"-")} -> CNE BNE 2024 | L15: {=_xlfn.XLOOKUP(E15&G15,'1.1 Combustión estacionaria'!$B$16:$B$48&'1.1 Combustión estacionaria'!$F$16:$F$48,'1.1 Combustión estacionaria'!$AF$16:$AF$48,"-")} -> -
B16: Emisiones directas | C16: 1.1 Combustión estacionaria | D16: Caldera/Generador/General | E16: Carbón térmico | F16: - | G16: gramos | H16: {=_xlfn.XLOOKUP(E16&G16,'1.1 Combustión estacionaria'!$B$16:$B$48&'1.1 Combustión estacionaria'!$F$16:$F$48,'1.1 Combustión estacionaria'!$AB$16:$AB$48,"-")} -> 0.0026527371 | I16: {=_xlfn.XLOOKUP(E16&G16,'1.1 Combustión estacionaria'!$B$16:$B$48&'1.1 Combustión estacionaria'!$F$16:$F$48,'1.1 Combustión estacionaria'!$AC$16:$AC$48,"-")} -> kgCO2e/gramos | J16: {=_xlfn.XLOOKUP(E16&G16,'1.1 Combustión estacionaria'!$B$16:$B$48&'1.1 Combustión estacionaria'!$F$16:$F$48,'1.1 Combustión estacionaria'!$AD$16:$AD$48,"-")} -> IPCC 2006 (vol2; chapter 2) , Table 2.4 | K16: {=_xlfn.XLOOKUP(E16&G16,'1.1 Combustión estacionaria'!$B$16:$B$48&'1.1 Combustión estacionaria'!$F$16:$F$48,'1.1 Combustión estacionaria'!$AE$16:$AE$48,"-")} -> CNE BNE 2024 | L16: {=_xlfn.XLOOKUP(E16&G16,'1.1 Combustión estacionaria'!$B$16:$B$48&'1.1 Combustión estacionaria'!$F$16:$F$48,'1.1 Combustión estacionaria'!$AF$16:$AF$48,"-")} -> -
B17: Emisiones directas | C17: 1.1 Combustión estacionaria | D17: Caldera/Generador/General | E17: Gasolina | F17: - | G17: metros cúbicos | H17: {=_xlfn.XLOOKUP(E17&G17,'1.1 Combustión estacionaria'!$B$16:$B$48&'1.1 Combustión estacionaria'!$F$16:$F$48,'1.1 Combustión estacionaria'!$AB$16:$AB$48,"-")} -> 2267.8923 | I17: {=_xlfn.XLOOKUP(E17&G17,'1.1 Combustión estacionaria'!$B$16:$B$48&'1.1 Combustión estacionaria'!$F$16:$F$48,'1.1 Combustión estacionaria'!$AC$16:$AC$48,"-")} -> kgCO2e/metros cúbicos | J17: {=_xlfn.XLOOKUP(E17&G17,'1.1 Combustión estacionaria'!$B$16:$B$48&'1.1 Combustión estacionaria'!$F$16:$F$48,'1.1 Combustión estacionaria'!$AD$16:$AD$48,"-")} -> IPCC 2006 (vol2; chapter 2) , Table 2.4 | K17: {=_xlfn.XLOOKUP(E17&G17,'1.1 Combustión estacionaria'!$B$16:$B$48&'1.1 Combustión estacionaria'!$F$16:$F$48,'1.1 Combustión estacionaria'!$AE$16:$AE$48,"-")} -> CNE BNE 2024 | L17: {=_xlfn.XLOOKUP(E17&G17,'1.1 Combustión estacionaria'!$B$16:$B$48&'1.1 Combustión estacionaria'!$F$16:$F$48,'1.1 Combustión estacionaria'!$AF$16:$AF$48,"-")} -> -
B18: Emisiones directas | C18: 1.1 Combustión estacionaria | D18: Caldera/Generador/General | E18: Gasolina | F18: - | G18: litros | H18: {=_xlfn.XLOOKUP(E18&G18,'1.1 Combustión estacionaria'!$B$16:$B$48&'1.1 Combustión estacionaria'!$F$16:$F$48,'1.1 Combustión estacionaria'!$AB$16:$AB$48,"-")} -> 2.2678923 | I18: {=_xlfn.XLOOKUP(E18&G18,'1.1 Combustión estacionaria'!$B$16:$B$48&'1.1 Combustión estacionaria'!$F$16:$F$48,'1.1 Combustión estacionaria'!$AC$16:$AC$48,"-")} -> kgCO2e/litros | J18: {=_xlfn.XLOOKUP(E18&G18,'1.1 Combustión estacionaria'!$B$16:$B$48&'1.1 Combustión estacionaria'!$F$16:$F$48,'1.1 Combustión estacionaria'!$AD$16:$AD$48,"-")} -> IPCC 2006 (vol2; chapter 2) , Table 2.4 | K18: {=_xlfn.XLOOKUP(E18&G18,'1.1 Combustión estacionaria'!$B$16:$B$48&'1.1 Combustión estacionaria'!$F$16:$F$48,'1.1 Combustión estacionaria'!$AE$16:$AE$48,"-")} -> CNE BNE 2024 | L18: {=_xlfn.XLOOKUP(E18&G18,'1.1 Combustión estacionaria'!$B$16:$B$48&'1.1 Combustión estacionaria'!$F$16:$F$48,'1.1 Combustión estacionaria'!$AF$16:$AF$48,"-")} -> -
B19: Emisiones directas | C19: 1.1 Combustión estacionaria | D19: Caldera/Generador/General | E19: Gas de alto horno | F19: - | G19: toneladas | H19: {=_xlfn.XLOOKUP(E19&G19,'1.1 Combustión estacionaria'!$B$16:$B$48&'1.1 Combustión estacionaria'!$F$16:$F$48,'1.1 Combustión estacionaria'!$AB$16:$AB$48,"-")} -> 578.35013 | I19: {=_xlfn.XLOOKUP(E19&G19,'1.1 Combustión estacionaria'!$B$16:$B$48&'1.1 Combustión estacionaria'!$F$16:$F$48,'1.1 Combustión estacionaria'!$AC$16:$AC$48,"-")} -> kgCO2e/toneladas | J19: {=_xlfn.XLOOKUP(E19&G19,'1.1 Combustión estacionaria'!$B$16:$B$48&'1.1 Combustión estacionaria'!$F$16:$F$48,'1.1 Combustión estacionaria'!$AD$16:$AD$48,"-")} -> IPCC 2006 (vol2; chapter 2) , Table 2.4 | K19: {=_xlfn.XLOOKUP(E19&G19,'1.1 Combustión estacionaria'!$B$16:$B$48&'1.1 Combustión estacionaria'!$F$16:$F$48,'1.1 Combustión estacionaria'!$AE$16:$AE$48,"-")} -> CNE BNE 2024 | L19: {=_xlfn.XLOOKUP(E19&G19,'1.1 Combustión estacionaria'!$B$16:$B$48&'1.1 Combustión estacionaria'!$F$16:$F$48,'1.1 Combustión estacionaria'!$AF$16:$AF$48,"-")} -> IPCC 2006 (vol2; chapter 1) , Table 1.2
B20: Emisiones directas | C20: 1.1 Combustión estacionaria | D20: Caldera/Generador/General | E20: Gas de alto horno | F20: - | G20: kilogramos | H20: {=_xlfn.XLOOKUP(E20&G20,'1.1 Combustión estacionaria'!$B$16:$B$48&'1.1 Combustión estacionaria'!$F$16:$F$48,'1.1 Combustión estacionaria'!$AB$16:$AB$48,"-")} -> 0.57835013 | I20: {=_xlfn.XLOOKUP(E20&G20,'1.1 Combustión estacionaria'!$B$16:$B$48&'1.1 Combustión estacionaria'!$F$16:$F$48,'1.1 Combustión estacionaria'!$AC$16:$AC$48,"-")} -> kgCO2e/kilogramos | J20: {=_xlfn.XLOOKUP(E20&G20,'1.1 Combustión estacionaria'!$B$16:$B$48&'1.1 Combustión estacionaria'!$F$16:$F$48,'1.1 Combustión estacionaria'!$AD$16:$AD$48,"-")} -> IPCC 2006 (vol2; chapter 2) , Table 2.4 | K20: {=_xlfn.XLOOKUP(E20&G20,'1.1 Combustión estacionaria'!$B$16:$B$48&'1.1 Combustión estacionaria'!$F$16:$F$48,'1.1 Combustión estacionaria'!$AE$16:$AE$48,"-")} -> CNE BNE 2024 | L20: {=_xlfn.XLOOKUP(E20&G20,'1.1 Combustión estacionaria'!$B$16:$B$48&'1.1 Combustión estacionaria'!$F$16:$F$48,'1.1 Combustión estacionaria'!$AF$16:$AF$48,"-")} -> IPCC 2006 (vol2; chapter 1) , Table 1.2
... B41: Emisiones directas | C41: 1.1 Combustión estacionaria | D41: Caldera/Generador/General | E41: Petróleo 6 | F41: - | G41: litros | H41: {=_xlfn.XLOOKUP(E41&G41,'1.1 Combustión estacionaria'!$B$16:$B$48&'1.1 Combustión estacionaria'!$F$16:$F$48,'1.1 Combustión estacionaria'!$AB$16:$AB$48,"-")} -> 3.072021 | I41: {=_xlfn.XLOOKUP(E41&G41,'1.1 Combustión estacionaria'!$B$16:$B$48&'1.1 Combustión estacionaria'!$F$16:$F$48,'1.1 Combustión estacionaria'!$AC$16:$AC$48,"-")} -> kgCO2e/litros | J41: {=_xlfn.XLOOKUP(E41&G41,'1.1 Combustión estacionaria'!$B$16:$B$48&'1.1 Combustión estacionaria'!$F$16:$F$48,'1.1 Combustión estacionaria'!$AD$16:$AD$48,"-")} -> IPCC 2006 (vol2; chapter 2) , Table 2.4 | K41: {=_xlfn.XLOOKUP(E41&G41,'1.1 Combustión estacionaria'!$B$16:$B$48&'1.1 Combustión estacionaria'!$F$16:$F$48,'1.1 Combustión estacionaria'!$AE$16:$AE$48,"-")} -> CNE BNE 2024 | L41: {=_xlfn.XLOOKUP(E41&G41,'1.1 Combustión estacionaria'!$B$16:$B$48&'1.1 Combustión estacionaria'!$F$16:$F$48,'1.1 Combustión estacionaria'!$AF$16:$AF$48,"-")} -> -
B42: Emisiones directas | C42: 1.2 Combustión móvil | D42: Vehíulos de pasajeros o carga | E42: Petróleo 2 (Diesel) | F42: - | G42: metros cúbicos | H42: {=_xlfn.XLOOKUP(E42&G42,'1.2 Combustión móvil'!$B$16:$B$24&'1.2 Combustión móvil'!$F$16:$F$24,'1.2 Combustión móvil'!$AB$16:$AB$24,"-")} -> 2740.1603 | I42: {=_xlfn.XLOOKUP(E42&G42,'1.2 Combustión móvil'!$B$16:$B$24&'1.2 Combustión móvil'!$F$16:$F$24,'1.2 Combustión móvil'!$AC$16:$AC$24,"-")} -> kgCO2e/metros cúbicos | J42: {=_xlfn.XLOOKUP(E42&G42,'1.2 Combustión móvil'!$B$16:$B$24&'1.2 Combustión móvil'!$F$16:$F$24,'1.2 Combustión móvil'!$AD$16:$AD$24,"-")} -> IPCC 2006 (vol2; chapter 3) , Table 3.2.1 and Table 3.2.2 | K42: {=_xlfn.XLOOKUP(E42&G42,'1.2 Combustión móvil'!$B$16:$B$24&'1.2 Combustión móvil'!$F$16:$F$24,'1.2 Combustión móvil'!$AE$16:$AE$24,"-")} -> CNE BNE 2024 | L42: {=_xlfn.XLOOKUP(E42&G42,'1.2 Combustión móvil'!$B$16:$B$24&'1.2 Combustión móvil'!$F$16:$F$24,'1.2 Combustión móvil'!$AF$16:$AF$24,"-")} -> -
B43: Emisiones directas | C43: 1.2 Combustión móvil | D43: Vehíulos de pasajeros o carga | E43: Petróleo 2 (Diesel) | F43: - | G43: litros | H43: {=_xlfn.XLOOKUP(E43&G43,'1.2 Combustión móvil'!$B$16:$B$24&'1.2 Combustión móvil'!$F$16:$F$24,'1.2 Combustión móvil'!$AB$16:$AB$24,"-")} -> 2.7401603 | I43: {=_xlfn.XLOOKUP(E43&G43,'1.2 Combustión móvil'!$B$16:$B$24&'1.2 Combustión móvil'!$F$16:$F$24,'1.2 Combustión móvil'!$AC$16:$AC$24,"-")} -> kgCO2e/litros | J43: {=_xlfn.XLOOKUP(E43&G43,'1.2 Combustión móvil'!$B$16:$B$24&'1.2 Combustión móvil'!$F$16:$F$24,'1.2 Combustión móvil'!$AD$16:$AD$24,"-")} -> IPCC 2006 (vol2; chapter 3) , Table 3.2.1 and Table 3.2.2 | K43: {=_xlfn.XLOOKUP(E43&G43,'1.2 Combustión móvil'!$B$16:$B$24&'1.2 Combustión móvil'!$F$16:$F$24,'1.2 Combustión móvil'!$AE$16:$AE$24,"-")} -> CNE BNE 2024 | L43: {=_xlfn.XLOOKUP(E43&G43,'1.2 Combustión móvil'!$B$16:$B$24&'1.2 Combustión móvil'!$F$16:$F$24,'1.2 Combustión móvil'!$AF$16:$AF$24,"-")} -> -
B44: Emisiones directas | C44: 1.2 Combustión móvil | D44: Vehíulos de pasajeros o carga | E44: Gas licuado | F44: - | G44: metros cúbicos | H44: {=_xlfn.XLOOKUP(E44&G44,'1.2 Combustión móvil'!$B$16:$B$24&'1.2 Combustión móvil'!$F$16:$F$24,'1.2 Combustión móvil'!$AB$16:$AB$24,"-")} -> 1717.6116 | I44: {=_xlfn.XLOOKUP(E44&G44,'1.2 Combustión móvil'!$B$16:$B$24&'1.2 Combustión móvil'!$F$16:$F$24,'1.2 Combustión móvil'!$AC$16:$AC$24,"-")} -> kgCO2e/metros cúbicos | J44: {=_xlfn.XLOOKUP(E44&G44,'1.2 Combustión móvil'!$B$16:$B$24&'1.2 Combustión móvil'!$F$16:$F$24,'1.2 Combustión móvil'!$AD$16:$AD$24,"-")} -> IPCC 2006 (vol2; chapter 3) , Table 3.2.1 and Table 3.2.2 | K44: {=_xlfn.XLOOKUP(E44&G44,'1.2 Combustión móvil'!$B$16:$B$24&'1.2 Combustión móvil'!$F$16:$F$24,'1.2 Combustión móvil'!$AE$16:$AE$24,"-")} -> CNE BNE 2024 | L44: {=_xlfn.XLOOKUP(E44&G44,'1.2 Combustión móvil'!$B$16:$B$24&'1.2 Combustión móvil'!$F$16:$F$24,'1.2 Combustión móvil'!$AF$16:$AF$24,"-")} -> -
B45: Emisiones directas | C45: 1.2 Combustión móvil | D45: Vehíulos de pasajeros o carga | E45: Gas licuado | F45: - | G45: litros | H45: {=_xlfn.XLOOKUP(E45&G45,'1.2 Combustión móvil'!$B$16:$B$24&'1.2 Combustión móvil'!$F$16:$F$24,'1.2 Combustión móvil'!$AB$16:$AB$24,"-")} -> 1.7176116 | I45: {=_xlfn.XLOOKUP(E45&G45,'1.2 Combustión móvil'!$B$16:$B$24&'1.2 Combustión móvil'!$F$16:$F$24,'1.2 Combustión móvil'!$AC$16:$AC$24,"-")} -> kgCO2e/litros | J45: {=_xlfn.XLOOKUP(E45&G45,'1.2 Combustión móvil'!$B$16:$B$24&'1.2 Combustión móvil'!$F$16:$F$24,'1.2 Combustión móvil'!$AD$16:$AD$24,"-")} -> IPCC 2006 (vol2; chapter 3) , Table 3.2.1 and Table 3.2.2 | K45: {=_xlfn.XLOOKUP(E45&G45,'1.2 Combustión móvil'!$B$16:$B$24&'1.2 Combustión móvil'!$F$16:$F$24,'1.2 Combustión móvil'!$AE$16:$AE$24,"-")} -> CNE BNE 2024 | L45: {=_xlfn.XLOOKUP(E45&G45,'1.2 Combustión móvil'!$B$16:$B$24&'1.2 Combustión móvil'!$F$16:$F$24,'1.2 Combustión móvil'!$AF$16:$AF$24,"-")} -> -
B46: Emisiones directas | C46: 1.2 Combustión móvil | D46: Vehíulos de pasajeros o carga | E46: Gas natural | F46: - | G46: metros cúbicos | H46: {=_xlfn.XLOOKUP(E46&G46,'1.2 Combustión móvil'!$B$16:$B$24&'1.2 Combustión móvil'!$F$16:$F$24,'1.2 Combustión móvil'!$AB$16:$AB$24,"-")} -> 2.0932608 | I46: {=_xlfn.XLOOKUP(E46&G46,'1.2 Combustión móvil'!$B$16:$B$24&'1.2 Combustión móvil'!$F$16:$F$24,'1.2 Combustión móvil'!$AC$16:$AC$24,"-")} -> kgCO2e/metros cúbicos | J46: {=_xlfn.XLOOKUP(E46&G46,'1.2 Combustión móvil'!$B$16:$B$24&'1.2 Combustión móvil'!$F$16:$F$24,'1.2 Combustión móvil'!$AD$16:$AD$24,"-")} -> IPCC 2006 (vol2; chapter 3) , Table 3.2.1 and Table 3.2.2 | K46: {=_xlfn.XLOOKUP(E46&G46,'1.2 Combustión móvil'!$B$16:$B$24&'1.2 Combustión móvil'!$F$16:$F$24,'1.2 Combustión móvil'!$AE$16:$AE$24,"-")} -> CNE BNE 2024 | L46: {=_xlfn.XLOOKUP(E46&G46,'1.2 Combustión móvil'!$B$16:$B$24&'1.2 Combustión móvil'!$F$16:$F$24,'1.2 Combustión móvil'!$AF$16:$AF$24,"-")} -> -
B47: Emisiones directas | C47: 1.2 Combustión móvil | D47: Vehíulos de pasajeros o carga | E47: Gasolina | F47: - | G47: metros cúbicos | H47: {=_xlfn.XLOOKUP(E47&G47,'1.2 Combustión móvil'!$B$16:$B$24&'1.2 Combustión móvil'!$F$16:$F$24,'1.2 Combustión móvil'!$AB$16:$AB$24,"-")} -> 2345.3217 | I47: {=_xlfn.XLOOKUP(E47&G47,'1.2 Combustión móvil'!$B$16:$B$24&'1.2 Combustión móvil'!$F$16:$F$24,'1.2 Combustión móvil'!$AC$16:$AC$24,"-")} -> kgCO2e/metros cúbicos | J47: {=_xlfn.XLOOKUP(E47&G47,'1.2 Combustión móvil'!$B$16:$B$24&'1.2 Combustión móvil'!$F$16:$F$24,'1.2 Combustión móvil'!$AD$16:$AD$24,"-")} -> IPCC 2006 (vol2; chapter 3) , Table 3.2.1 and Table 3.2.2 | K47: {=_xlfn.XLOOKUP(E47&G47,'1.2 Combustión móvil'!$B$16:$B$24&'1.2 Combustión móvil'!$F$16:$F$24,'1.2 Combustión móvil'!$AE$16:$AE$24,"-")} -> CNE BNE 2024 | L47: {=_xlfn.XLOOKUP(E47&G47,'1.2 Combustión móvil'!$B$16:$B$24&'1.2 Combustión móvil'!$F$16:$F$24,'1.2 Combustión móvil'!$AF$16:$AF$24,"-")} -> -
B48: Emisiones directas | C48: 1.2 Combustión móvil | D48: Vehíulos de pasajeros o carga | E48: Gasolina | F48: - | G48: litros | H48: {=_xlfn.XLOOKUP(E48&G48,'1.2 Combustión móvil'!$B$16:$B$24&'1.2 Combustión móvil'!$F$16:$F$24,'1.2 Combustión móvil'!$AB$16:$AB$24,"-")} -> 2.3453217 | I48: {=_xlfn.XLOOKUP(E48&G48,'1.2 Combustión móvil'!$B$16:$B$24&'1.2 Combustión móvil'!$F$16:$F$24,'1.2 Combustión móvil'!$AC$16:$AC$24,"-")} -> kgCO2e/litros | J48: {=_xlfn.XLOOKUP(E48&G48,'1.2 Combustión móvil'!$B$16:$B$24&'1.2 Combustión móvil'!$F$16:$F$24,'1.2 Combustión móvil'!$AD$16:$AD$24,"-")} -> IPCC 2006 (vol2; chapter 3) , Table 3.2.1 and Table 3.2.2 | K48: {=_xlfn.XLOOKUP(E48&G48,'1.2 Combustión móvil'!$B$16:$B$24&'1.2 Combustión móvil'!$F$16:$F$24,'1.2 Combustión móvil'!$AE$16:$AE$24,"-")} -> CNE BNE 2024 | L48: {=_xlfn.XLOOKUP(E48&G48,'1.2 Combustión móvil'!$B$16:$B$24&'1.2 Combustión móvil'!$F$16:$F$24,'1.2 Combustión móvil'!$AF$16:$AF$24,"-")} -> -
B49: Emisiones directas | C49: 1.2 Combustión móvil | D49: Vehíulos de pasajeros o carga | E49: Kerosene | F49: - | G49: metros cúbicos | H49: {=_xlfn.XLOOKUP(E49&G49,'1.2 Combustión móvil'!$B$16:$B$24&'1.2 Combustión móvil'!$F$16:$F$24,'1.2 Combustión móvil'!$AB$16:$AB$24,"-")} -> 2579.9306 | I49: {=_xlfn.XLOOKUP(E49&G49,'1.2 Combustión móvil'!$B$16:$B$24&'1.2 Combustión móvil'!$F$16:$F$24,'1.2 Combustión móvil'!$AC$16:$AC$24,"-")} -> kgCO2e/metros cúbicos | J49: {=_xlfn.XLOOKUP(E49&G49,'1.2 Combustión móvil'!$B$16:$B$24&'1.2 Combustión móvil'!$F$16:$F$24,'1.2 Combustión móvil'!$AD$16:$AD$24,"-")} -> IPCC 2006 (vol2; chapter 3) , Table 3.2.1 and Table 3.2.2 | K49: {=_xlfn.XLOOKUP(E49&G49,'1.2 Combustión móvil'!$B$16:$B$24&'1.2 Combustión móvil'!$F$16:$F$24,'1.2 Combustión móvil'!$AE$16:$AE$24,"-")} -> CNE BNE 2024 | L49: {=_xlfn.XLOOKUP(E49&G49,'1.2 Combustión móvil'!$B$16:$B$24&'1.2 Combustión móvil'!$F$16:$F$24,'1.2 Combustión móvil'!$AF$16:$AF$24,"-")} -> IPCC 2006 (vol2; chapter 2), Table 2.3
B50: Emisiones directas | C50: 1.2 Combustión móvil | D50: Vehíulos de pasajeros o carga | E50: Kerosene | F50: - | G50: litros | H50: {=_xlfn.XLOOKUP(E50&G50,'1.2 Combustión móvil'!$B$16:$B$24&'1.2 Combustión móvil'!$F$16:$F$24,'1.2 Combustión móvil'!$AB$16:$AB$24,"-")} -> 2.5799306 | I50: {=_xlfn.XLOOKUP(E50&G50,'1.2 Combustión móvil'!$B$16:$B$24&'1.2 Combustión móvil'!$F$16:$F$24,'1.2 Combustión móvil'!$AC$16:$AC$24,"-")} -> kgCO2e/litros | J50: {=_xlfn.XLOOKUP(E50&G50,'1.2 Combustión móvil'!$B$16:$B$24&'1.2 Combustión móvil'!$F$16:$F$24,'1.2 Combustión móvil'!$AD$16:$AD$24,"-")} -> IPCC 2006 (vol2; chapter 3) , Table 3.2.1 and Table 3.2.2 | K50: {=_xlfn.XLOOKUP(E50&G50,'1.2 Combustión móvil'!$B$16:$B$24&'1.2 Combustión móvil'!$F$16:$F$24,'1.2 Combustión móvil'!$AE$16:$AE$24,"-")} -> CNE BNE 2024 | L50: {=_xlfn.XLOOKUP(E50&G50,'1.2 Combustión móvil'!$B$16:$B$24&'1.2 Combustión móvil'!$F$16:$F$24,'1.2 Combustión móvil'!$AF$16:$AF$24,"-")} -> IPCC 2006 (vol2; chapter 2), Table 2.3
B51: Emisiones directas | C51: 1.3 Procesos industriales | D51: Producción minerales | E51: Producción de cemento | F51: - | G51: toneladas | H51: {=_xlfn.XLOOKUP(E51&G51,'1.3 Procesos industriales'!$B$12:$B$67&'1.3 Procesos industriales'!$C$12:$C$67,'1.3 Procesos industriales'!$T$12:$T$67,"-")} -> 316.8324 | I51: {=_xlfn.XLOOKUP(E51&G51,'1.3 Procesos industriales'!$B$12:$B$67&'1.3 Procesos industriales'!$C$12:$C$67,'1.3 Procesos industriales'!$U$12:$U$67,"-")} -> kgCO2e/toneladas | J51: {=_xlfn.XLOOKUP(E51&G51,'1.3 Procesos industriales'!$B$12:$B$67&'1.3 Procesos industriales'!$C$12:$C$67,'1.3 Procesos industriales'!$V$12:$V$67,"-")} -> INGEI + IPCC 2006. Ver su hoja correspondiente para más detalles. | K51: - | L51: -
B52: Emisiones directas | C52: 1.3 Procesos industriales | D52: Producción minerales | E52: Producción de cemento | F52: - | G52: kilogramos | H52: {=_xlfn.XLOOKUP(E52&G52,'1.3 Procesos industriales'!$B$12:$B$67&'1.3 Procesos industriales'!$C$12:$C$67,'1.3 Procesos industriales'!$T$12:$T$67,"-")} -> 0.3168324 | I52: {=_xlfn.XLOOKUP(E52&G52,'1.3 Procesos industriales'!$B$12:$B$67&'1.3 Procesos industriales'!$C$12:$C$67,'1.3 Procesos industriales'!$U$12:$U$67,"-")} -> kgCO2e/kilogramos | J52: {=_xlfn.XLOOKUP(E52&G52,'1.3 Procesos industriales'!$B$12:$B$67&'1.3 Procesos industriales'!$C$12:$C$67,'1.3 Procesos industriales'!$V$12:$V$67,"-")} -> INGEI + IPCC 2006. Ver su hoja correspondiente para más detalles. | K52: - | L52: -
B53: Emisiones directas | C53: 1.3 Procesos industriales | D53: Producción minerales | E53: Producción de cemento | F53: - | G53: gramos | H53: {=_xlfn.XLOOKUP(E53&G53,'1.3 Procesos industriales'!$B$12:$B$67&'1.3 Procesos industriales'!$C$12:$C$67,'1.3 Procesos industriales'!$T$12:$T$67,"-")} -> 0.0003168324 | I53: {=_xlfn.XLOOKUP(E53&G53,'1.3 Procesos industriales'!$B$12:$B$67&'1.3 Procesos industriales'!$C$12:$C$67,'1.3 Procesos industriales'!$U$12:$U$67,"-")} -> kgCO2e/gramos | J53: {=_xlfn.XLOOKUP(E53&G53,'1.3 Procesos industriales'!$B$12:$B$67&'1.3 Procesos industriales'!$C$12:$C$67,'1.3 Procesos industriales'!$V$12:$V$67,"-")} -> INGEI + IPCC 2006. Ver su hoja correspondiente para más detalles. | K53: - | L53: -
B54: Emisiones directas | C54: 1.3 Procesos industriales | D54: Producción minerales | E54: Producción de cal | F54: - | G54: toneladas | H54: {=_xlfn.XLOOKUP(E54&G54,'1.3 Procesos industriales'!$B$12:$B$67&'1.3 Procesos industriales'!$C$12:$C$67,'1.3 Procesos industriales'!$T$12:$T$67,"-")} -> 695.1277 | I54: {=_xlfn.XLOOKUP(E54&G54,'1.3 Procesos industriales'!$B$12:$B$67&'1.3 Procesos industriales'!$C$12:$C$67,'1.3 Procesos industriales'!$U$12:$U$67,"-")} -> kgCO2e/toneladas | J54: {=_xlfn.XLOOKUP(E54&G54,'1.3 Procesos industriales'!$B$12:$B$67&'1.3 Procesos industriales'!$C$12:$C$67,'1.3 Procesos industriales'!$V$12:$V$67,"-")} -> INGEI + IPCC 2006. Ver su hoja correspondiente para más detalles. | K54: - | L54: -
B55: Emisiones directas | C55: 1.3 Procesos industriales | D55: Producción minerales | E55: Producción de cal | F55: - | G55: kilogramos | H55: {=_xlfn.XLOOKUP(E55&G55,'1.3 Procesos industriales'!$B$12:$B$67&'1.3 Procesos industriales'!$C$12:$C$67,'1.3 Procesos industriales'!$T$12:$T$67,"-")} -> 0.6951277 | I55: {=_xlfn.XLOOKUP(E55&G55,'1.3 Procesos industriales'!$B$12:$B$67&'1.3 Procesos industriales'!$C$12:$C$67,'1.3 Procesos industriales'!$U$12:$U$67,"-")} -> kgCO2e/kilogramos | J55: {=_xlfn.XLOOKUP(E55&G55,'1.3 Procesos industriales'!$B$12:$B$67&'1.3 Procesos industriales'!$C$12:$C$67,'1.3 Procesos industriales'!$V$12:$V$67,"-")} -> INGEI + IPCC 2006. Ver su hoja correspondiente para más detalles. | K55: - | L55: -
B56: Emisiones directas | C56: 1.3 Procesos industriales | D56: Producción minerales | E56: Producción de cal | F56: - | G56: gramos | H56: {=_xlfn.XLOOKUP(E56&G56,'1.3 Procesos industriales'!$B$12:$B$67&'1.3 Procesos industriales'!$C$12:$C$67,'1.3 Procesos industriales'!$T$12:$T$67,"-")} -> 0.00069512771 | I56: {=_xlfn.XLOOKUP(E56&G56,'1.3 Procesos industriales'!$B$12:$B$67&'1.3 Procesos industriales'!$C$12:$C$67,'1.3 Procesos industriales'!$U$12:$U$67,"-")} -> kgCO2e/gramos | J56: {=_xlfn.XLOOKUP(E56&G56,'1.3 Procesos industriales'!$B$12:$B$67&'1.3 Procesos industriales'!$C$12:$C$67,'1.3 Procesos industriales'!$V$12:$V$67,"-")} -> INGEI + IPCC 2006. Ver su hoja correspondiente para más detalles. | K56: - | L56: -
B57: Emisiones directas | C57: 1.3 Procesos industriales | D57: Producción minerales | E57: Producción de vidrio | F57: - | G57: toneladas | H57: {=_xlfn.XLOOKUP(E57&G57,'1.3 Procesos industriales'!$B$12:$B$67&'1.3 Procesos industriales'!$C$12:$C$67,'1.3 Procesos industriales'!$T$12:$T$67,"-")} -> 145.16437 | I57: {=_xlfn.XLOOKUP(E57&G57,'1.3 Procesos industriales'!$B$12:$B$67&'1.3 Procesos industriales'!$C$12:$C$67,'1.3 Procesos industriales'!$U$12:$U$67,"-")} -> kgCO2e/toneladas | J57: {=_xlfn.XLOOKUP(E57&G57,'1.3 Procesos industriales'!$B$12:$B$67&'1.3 Procesos industriales'!$C$12:$C$67,'1.3 Procesos industriales'!$V$12:$V$67,"-")} -> INGEI + IPCC 2006. Ver su hoja correspondiente para más detalles. | K57: - | L57: -
B58: Emisiones directas | C58: 1.3 Procesos industriales | D58: Producción minerales | E58: Producción de vidrio | F58: - | G58: kilogramos | H58: {=_xlfn.XLOOKUP(E58&G58,'1.3 Procesos industriales'!$B$12:$B$67&'1.3 Procesos industriales'!$C$12:$C$67,'1.3 Procesos industriales'!$T$12:$T$67,"-")} -> 0.14516437 | I58: {=_xlfn.XLOOKUP(E58&G58,'1.3 Procesos industriales'!$B$12:$B$67&'1.3 Procesos industriales'!$C$12:$C$67,'1.3 Procesos industriales'!$U$12:$U$67,"-")} -> kgCO2e/kilogramos | J58: {=_xlfn.XLOOKUP(E58&G58,'1.3 Procesos industriales'!$B$12:$B$67&'1.3 Procesos industriales'!$C$12:$C$67,'1.3 Procesos industriales'!$V$12:$V$67,"-")} -> INGEI + IPCC 2006. Ver su hoja correspondiente para más detalles. | K58: - | L58: -
B59: Emisiones directas | C59: 1.3 Procesos industriales | D59: Producción minerales | E59: Producción de vidrio | F59: - | G59: gramos | H59: {=_xlfn.XLOOKUP(E59&G59,'1.3 Procesos industriales'!$B$12:$B$67&'1.3 Procesos industriales'!$C$12:$C$67,'1.3 Procesos industriales'!$T$12:$T$67,"-")} -> 0.00014516437 | I59: {=_xlfn.XLOOKUP(E59&G59,'1.3 Procesos industriales'!$B$12:$B$67&'1.3 Procesos industriales'!$C$12:$C$67,'1.3 Procesos industriales'!$U$12:$U$67,"-")} -> kgCO2e/gramos | J59: {=_xlfn.XLOOKUP(E59&G59,'1.3 Procesos industriales'!$B$12:$B$67&'1.3 Procesos industriales'!$C$12:$C$67,'1.3 Procesos industriales'!$V$12:$V$67,"-")} -> INGEI + IPCC 2006. Ver su hoja correspondiente para más detalles. | K59: - | L59: -
B60: Emisiones directas | C60: 1.3 Procesos industriales | D60: Producción minerales | E60: Producción de coke | F60: - | G60: toneladas | H60: {=_xlfn.XLOOKUP(E60&G60,'1.3 Procesos industriales'!$B$12:$B$67&'1.3 Procesos industriales'!$C$12:$C$67,'1.3 Procesos industriales'!$T$12:$T$67,"-")} -> 560.0028 | I60: {=_xlfn.XLOOKUP(E60&G60,'1.3 Procesos industriales'!$B$12:$B$67&'1.3 Procesos industriales'!$C$12:$C$67,'1.3 Procesos industriales'!$U$12:$U$67,"-")} -> kgCO2e/toneladas | J60: {=_xlfn.XLOOKUP(E60&G60,'1.3 Procesos industriales'!$B$12:$B$67&'1.3 Procesos industriales'!$C$12:$C$67,'1.3 Procesos industriales'!$V$12:$V$67,"-")} -> INGEI + IPCC 2006. Ver su hoja correspondiente para más detalles. | K60: - | L60: -
B61: Emisiones directas | C61: 1.3 Procesos industriales | D61: Producción minerales | E61: Producción de coke | F61: - | G61: kilogramos | H61: {=_xlfn.XLOOKUP(E61&G61,'1.3 Procesos industriales'!$B$12:$B$67&'1.3 Procesos industriales'!$C$12:$C$67,'1.3 Procesos industriales'!$T$12:$T$67,"-")} -> 0.5600028 | I61: {=_xlfn.XLOOKUP(E61&G61,'1.3 Procesos industriales'!$B$12:$B$67&'1.3 Procesos industriales'!$C$12:$C$67,'1.3 Procesos industriales'!$U$12:$U$67,"-")} -> kgCO2e/kilogramos | J61: {=_xlfn.XLOOKUP(E61&G61,'1.3 Procesos industriales'!$B$12:$B$67&'1.3 Procesos industriales'!$C$12:$C$67,'1.3 Procesos industriales'!$V$12:$V$67,"-")} -> INGEI + IPCC 2006. Ver su hoja correspondiente para más detalles. | K61: - | L61: -
B62: Emisiones directas | C62: 1.3 Procesos industriales | D62: Producción minerales | E62: Producción de coke | F62: - | G62: gramos | H62: {=_xlfn.XLOOKUP(E62&G62,'1.3 Procesos industriales'!$B$12:$B$67&'1.3 Procesos industriales'!$C$12:$C$67,'1.3 Procesos industriales'!$T$12:$T$67,"-")} -> 0.0005600028 | I62: {=_xlfn.XLOOKUP(E62&G62,'1.3 Procesos industriales'!$B$12:$B$67&'1.3 Procesos industriales'!$C$12:$C$67,'1.3 Procesos industriales'!$U$12:$U$67,"-")} -> kgCO2e/gramos | J62: {=_xlfn.XLOOKUP(E62&G62,'1.3 Procesos industriales'!$B$12:$B$67&'1.3 Procesos industriales'!$C$12:$C$67,'1.3 Procesos industriales'!$V$12:$V$67,"-")} -> INGEI + IPCC 2006. Ver su hoja correspondiente para más detalles. | K62: - | L62: -
... B92: Emisiones directas | C92: 1.3 Procesos industriales | D92: Industria química | E92: Producción de ácido nítrico (Plantas a alta presión) | F92: - | G92: gramos | H92: {=_xlfn.XLOOKUP(E92&G92,'1.3 Procesos industriales'!$B$12:$B$67&'1.3 Procesos industriales'!$C$12:$C$67,'1.3 Procesos industriales'!$T$12:$T$67,"-")} -> 0.0026235 | I92: {=_xlfn.XLOOKUP(E92&G92,'1.3 Procesos industriales'!$B$12:$B$67&'1.3 Procesos industriales'!$C$12:$C$67,'1.3 Procesos industriales'!$U$12:$U$67,"-")} -> kgCO2e/gramos | J92: {=_xlfn.XLOOKUP(E92&G92,'1.3 Procesos industriales'!$B$12:$B$67&'1.3 Procesos industriales'!$C$12:$C$67,'1.3 Procesos industriales'!$V$12:$V$67,"-")} -> INGEI + IPCC 2006. Ver su hoja correspondiente para más detalles. | K92: - | L92: -
B93: Emisiones directas | C93: 1.4 Emisiones fugitivas | D93: Emisiones fugitivas | E93: HFC-245fa | F93: - | G93: kilogramos | H93: {=_xlfn.XLOOKUP(E93&G93,'1.4 Emisiones fugitivas'!$C$7:$C$61&'1.4 Emisiones fugitivas'!$F$7:$F$61,'1.4 Emisiones fugitivas'!$G$7:$G$61,"-")} -> 858 | I93: {=_xlfn.XLOOKUP(E93&G93,'1.4 Emisiones fugitivas'!$C$7:$C$61&'1.4 Emisiones fugitivas'!$F$7:$F$61,'1.4 Emisiones fugitivas'!$H$7:$H$61,"-")} -> kgCO2e/kilogramos | J93: {=_xlfn.XLOOKUP(E93&G93,'1.4 Emisiones fugitivas'!$C$7:$C$61&'1.4 Emisiones fugitivas'!$F$7:$F$61,'1.4 Emisiones fugitivas'!$I$7:$I$61,"-")} -> IPCC 2006 (vol3; chapter 7) , Table 7.8 | IPCC 2012 (AR5; chapter 8), Table 8.A.1 | K93: - | L93: -
B94: Emisiones directas | C94: 1.4 Emisiones fugitivas | D94: Emisiones fugitivas | E94: HFC-32 | F94: - | G94: kilogramos | H94: {=_xlfn.XLOOKUP(E94&G94,'1.4 Emisiones fugitivas'!$C$7:$C$61&'1.4 Emisiones fugitivas'!$F$7:$F$61,'1.4 Emisiones fugitivas'!$G$7:$G$61,"-")} -> 677 | I94: {=_xlfn.XLOOKUP(E94&G94,'1.4 Emisiones fugitivas'!$C$7:$C$61&'1.4 Emisiones fugitivas'!$F$7:$F$61,'1.4 Emisiones fugitivas'!$H$7:$H$61,"-")} -> kgCO2e/kilogramos | J94: {=_xlfn.XLOOKUP(E94&G94,'1.4 Emisiones fugitivas'!$C$7:$C$61&'1.4 Emisiones fugitivas'!$F$7:$F$61,'1.4 Emisiones fugitivas'!$I$7:$I$61,"-")} -> IPCC 2006 (vol3; chapter 7) , Table 7.8 | IPCC 2012 (AR5; chapter 8), Table 8.A.1 | K94: - | L94: -
B95: Emisiones directas | C95: 1.4 Emisiones fugitivas | D95: Emisiones fugitivas | E95: HFC-41 | F95: - | G95: kilogramos | H95: {=_xlfn.XLOOKUP(E95&G95,'1.4 Emisiones fugitivas'!$C$7:$C$61&'1.4 Emisiones fugitivas'!$F$7:$F$61,'1.4 Emisiones fugitivas'!$G$7:$G$61,"-")} -> 116 | I95: {=_xlfn.XLOOKUP(E95&G95,'1.4 Emisiones fugitivas'!$C$7:$C$61&'1.4 Emisiones fugitivas'!$F$7:$F$61,'1.4 Emisiones fugitivas'!$H$7:$H$61,"-")} -> kgCO2e/kilogramos | J95: {=_xlfn.XLOOKUP(E95&G95,'1.4 Emisiones fugitivas'!$C$7:$C$61&'1.4 Emisiones fugitivas'!$F$7:$F$61,'1.4 Emisiones fugitivas'!$I$7:$I$61,"-")} -> IPCC 2006 (vol3; chapter 7) , Table 7.8 | IPCC 2012 (AR5; chapter 8), Table 8.A.1 | K95: - | L95: -
B96: Emisiones directas | C96: 1.4 Emisiones fugitivas | D96: Emisiones fugitivas | E96: HFC-43-I0mee | F96: - | G96: kilogramos | H96: {=_xlfn.XLOOKUP(E96&G96,'1.4 Emisiones fugitivas'!$C$7:$C$61&'1.4 Emisiones fugitivas'!$F$7:$F$61,'1.4 Emisiones fugitivas'!$G$7:$G$61,"-")} -> 1650 | I96: {=_xlfn.XLOOKUP(E96&G96,'1.4 Emisiones fugitivas'!$C$7:$C$61&'1.4 Emisiones fugitivas'!$F$7:$F$61,'1.4 Emisiones fugitivas'!$H$7:$H$61,"-")} -> kgCO2e/kilogramos | J96: {=_xlfn.XLOOKUP(E96&G96,'1.4 Emisiones fugitivas'!$C$7:$C$61&'1.4 Emisiones fugitivas'!$F$7:$F$61,'1.4 Emisiones fugitivas'!$I$7:$I$61,"-")} -> IPCC 2006 (vol3; chapter 7) , Table 7.8 | IPCC 2012 (AR5; chapter 8), Table 8.A.1 | K96: - | L96: -
...

Sheet CONTROL DE CAMBIOS
B8: Versión | C8: Categoría (Hoja) | D8: Subcategoría | E8: Cambios realizados
B9: 1 | C9: 2.1 Electricidad | D9: Sistema Electrico Nacional | E9: Se actualiza de manera retoactiva los factores de emisión desde 2021 a 2025, según información de Energía Abierta (Ministerio de Energía)
B10: 1 | C10: 2.1 Electricidad | D10: Sistemas Electricos Medianos | E10: En espera de publicación de FE para sistemas medianos desde Energía Abierta (Ministerio de Energía)
B11: 1 | C11: 2.2 Perdidas por T&D | D11: Sistema Electrico Nacional | E11: Se actualiza de manera retoactiva los factores de emisión desde 2021 a 2025, según información de Energía Abierta (Ministerio de Energía)
B12: 1 | C12: 2.2 Perdidas por T&D | D12: Sistemas Electricos Medianos | E12: En espera de publicación de FE para sistemas medianos desde Energía Abierta (Ministerio de Energía)
B13: 1 | C13: 1.1 y 1.2CUADROA1 - BNE 2024 | D13: - | E13: Se actualiza información de Densidades y Poderes Caloríficos de combustibles (sin variaciones respecto a FE 2024)
B14: 1 | C14: 3.1 Adq. Bienes y servicios | D14: - | E14: Se actualizan factores de emisión DEFRA 2025
B15: 1 | C15: 3.2 Transporte de personas | D15: - | E15: Se actualizan factores de emisión DEFRA 2025
B16: 1 | C16: 3.3 Transporte de carga | D16: - | E16: Se actualizan factores de emisión DEFRA 2025
B17: 1 | C17: 3.4 Transporte de residuos | D17: - | E17: Se actualizan factores de emisión DEFRA 2025
B18: 1 | C18: 3.6 Trat. yo disp. de residuos | D18: - | E18: Se actualizan factores de emisión DEFRA 2025
B19: 2 | C19: 2.1 Electricidad | D19: Sistema Electrico Nacional Sistemas Electricos Medianos | E19: Se cambia el nombre de la fuente de origen de los factores para indicar que se utiliza AR5
B20: 2 | C20: 3.2 Transporte de personas | D20: Vehículo eléctrico y Van Electrico | E20: Se actualizan factores de emisión, en base a cálculo realizado por el Programa HuellaChile

Sheet 1.1 Combustión estacionaria
A1: Volver al INICIO
A2: Volver al RESUMEN | B2: Compuesto | C2: Valor | D2: Unidad | E2: Fuente
B3: Dióxido de Carbono (CO2) | C3: ='1.4 AR5 CH8 T8.A.1'!H4 -> 1 | D3: - | E3: AR5
B4: Metano (CH4) | C4: ='1.4 AR5 CH8 T8.A.1'!H5 -> 28 | D4: - | E4: AR5
B5: Óxido Nitroso (N2O) | C5: ='1.4 AR5 CH8 T8.A.1'!H7 -> 265 | D5: - | E5: AR5
B6: 1 kcal | C6: 4.1868 | D6: kJ | E6: IPCC Anex II: Metrics & Methodology
B7: 1 TJ | C7: 1000000000 | D7: kJ
B8: Combustibles sólidos y líquidos | C8: 0.95 | D8: - | E8: IPCC V2 CH1 (int. de confianza 95%)
B9: Combustibles gaseosos | C9: 0.9 | D9: - | E9: IPCC V2 CH1 (int. de confianza 90%)
B11: Huella Organizacional
B12: Emisiones directas
B13: Tipo de fuente: Caldera/Generador/General
T14: kg GEI/unidad | X14: CO2e/unidad
B15: Nombre en HuellaChile | C15: Nombre en BNE 2020 | D15: Nombre en IPCC ESP | E15: Nombre en IPCC EN | F15: Unidad del dato de actividad | G15: Estado del combustible | H15: CO2 kgCO2/TJ | I15: CH4 kgCH4/TJ | J15: N2O kgN2O/TJ | K15: Densidad | L15: Unidad | M15: Poder Calorífico Superior (PCS) | N15: Unidad PCS | O15: Poder Calorífico Inferior (PCI) | P15: Unidad PCI | Q15: Multiplica densidad | R15: PCI | S15: Unidad | T15: CO2 | U15: CH4 | V15: N2O | W15: Unidad | X15: CO2 | Y15: CH4 | Z15: N2O | AA15: Unidad | AB15: kgCO2e total | AC15: Unidad | AD15: Fuente 1 | AE15: Fuente 2 | AF15: Otras fuentes
B16: Nafta | C16: Nafta | D16: Nafta | E16: Naphtha | F16: metros cúbicos | G16: Líquido | H16: ='1.1 V2 CH2 T2.4'!$F$18 -> 73300 | I16: ='1.1 V2 CH2 T2.4'!$I$18 -> 10 | J16: ='1.1 V2 CH2 T2.4'!$L$18 -> 0.6 | K16: ='1.1 y 1.2CUADROA1 - BNE 2024'!$C$14 -> 0.7 | L16: t/m3 | M16: ='1.1 y 1.2CUADROA1 - BNE 2024'!D$14 -> 11500 | N16: ='1.1 y 1.2CUADROA1 - BNE 2024'!E$14 -> kCal/kg | O16: =IF(G16="Gaseoso", M16*$C$9, M16*$C$8) -> 10925 | P16: =N16 -> kCal/kg | Q16: Sí | R16: =O16*$C$6/$C$7*IF(Q16="Sí",K16*1000,1) -> 0.032018553 | S16: =IF(Q16="Sí","TJ/m3", IF(N16="kcal/m3", "TJ/m3","TJ/kg")) -> TJ/m3 | T16: =H16*$R16 -> 2346.9599 | U16: =I16*$R16 -> 0.32018553 | V16: =J16*$R16 -> 0.019211132 | W16: =IF(S16="TJ/m3", "kg GEI/m3", "kg GEI/kg") -> kg GEI/m3 | X16: =$C$3*T16 -> 2346.9599 | Y16: =U16*$C$4 -> 8.9651948 | Z16: =V16*$C$5 -> 5.0909499 | AA16: =IF(S16="TJ/m3", "kg CO2e/m3", "kg CO2e/kg") -> kg CO2e/m3 | AB16: =SUM(X16:Z16)*IF(AND(F16="gramos",S16="TJ/m3")=TRUE(),1/(K16*1000000), IF(AND(F16="gramos",S16="TJ/kg")=TRUE(),1/(1000), IF(AND(F16="kilogramos",S16="TJ/m3")=TRUE(),1/(K16*1000), IF(AND(F16="toneladas",S16="TJ/m3")=TRUE(),1/K16, IF(AND(F16="toneladas",S16="TJ/kg")=TRUE(),1000, IF(AND(S16="TJ/m3",F16="litros")=TRUE(),1/1000, IF(AND(S16="TJ/kg",F16="litros")=TRUE(),K16/1000,1))))))) -> 2361.0161 | AC16: ="kgCO2e/"&F16 -> kgCO2e/metros cúbicos | AD16: IPCC 2006 (vol2; chapter 2) , Table 2.4 | AE16: CNE BNE 2024 | AF16: -
B17: Nafta | C17: Nafta | D17: Nafta | E17: Naphtha | F17: litros | G17: Líquido | H17: ='1.1 V2 CH2 T2.4'!$F$18 -> 73300 | I17: ='1.1 V2 CH2 T2.4'!$I$18 -> 10 | J17: ='1.1 V2 CH2 T2.4'!$L$18 -> 0.6 | K17: ='1.1 y 1.2CUADROA1 - BNE 2024'!$C$14 -> 0.7 | L17: t/m3 | M17: ='1.1 y 1.2CUADROA1 - BNE 2024'!D$14 -> 11500 | N17: ='1.1 y 1.2CUADROA1 - BNE 2024'!E$14 -> kCal/kg | O17: =IF(G17="Gaseoso", M17*$C$9, M17*$C$8) -> 10925 | P17: =N17 -> kCal/kg | Q17: Sí | R17: =O17*$C$6/$C$7*IF(Q17="Sí",K17*1000,1) -> 0.032018553 | S17: =IF(Q17="Sí","TJ/m3", IF(N17="kcal/m3", "TJ/m3","TJ/kg")) -> TJ/m3 | T17: =H17*$R17 -> 2346.9599 | U17: =I17*$R17 -> 0.32018553 | V17: =J17*$R17 -> 0.019211132 | W17: =IF(S17="TJ/m3", "kg GEI/m3", "kg GEI/kg") -> kg GEI/m3 | X17: =$C$3*T17 -> 2346.9599 | Y17: =U17*$C$4 -> 8.9651948 | Z17: =V17*$C$5 -> 5.0909499 | AA17: =IF(S17="TJ/m3", "kg CO2e/m3", "kg CO2e/kg") -> kg CO2e/m3 | AB17: =SUM(X17:Z17)*IF(AND(F17="gramos",S17="TJ/m3")=TRUE(),1/(K17*1000000), IF(AND(F17="gramos",S17="TJ/kg")=TRUE(),1/(1000), IF(AND(F17="kilogramos",S17="TJ/m3")=TRUE(),1/(K17*1000), IF(AND(F17="toneladas",S17="TJ/m3")=TRUE(),1/K17, IF(AND(F17="toneladas",S17="TJ/kg")=TRUE(),1000, IF(AND(S17="TJ/m3",F17="litros")=TRUE(),1/1000, IF(AND(S17="TJ/kg",F17="litros")=TRUE(),K17/1000,1))))))) -> 2.3610161 | AC17: ="kgCO2e/"&F17 -> kgCO2e/litros | AD17: IPCC 2006 (vol2; chapter 2) , Table 2.4 | AE17: CNE BNE 2024 | AF17: -
B18: Carbón metalúrgico | C18: Carbón | D18: Carbón de coque | E18: Coking Coal | F18: toneladas | G18: Sólido | H18: ='1.1 V2 CH2 T2.4'!$F$29 -> 94600 | I18: ='1.1 V2 CH2 T2.4'!$I$29 -> 10 | J18: ='1.1 V2 CH2 T2.4'!$L$29 -> 1.5 | M18: ='1.1 y 1.2CUADROA1 - BNE 2024'!D$26 -> 7000 | N18: ='1.1 y 1.2CUADROA1 - BNE 2024'!E$23 -> kCal/kg | O18: =IF(G18="Gaseoso", M18*$C$9, M18*$C$8) -> 6650 | P18: =N18 -> kCal/kg | Q18: No | R18: =O18*$C$6/$C$7*IF(Q18="Sí",K18*1000,1) -> 2.784222e-05 | S18: =IF(Q18="Sí","TJ/m3", IF(N18="kcal/m3", "TJ/m3","TJ/kg")) -> TJ/kg | T18: =H18*$R18 -> 2.633874 | U18: =I18*$R18 -> 0.0002784222 | V18: =J18*$R18 -> 4.176333e-05 | W18: =IF(S18="TJ/m3", "kg GEI/m3", "kg GEI/kg") -> kg GEI/kg | X18: =$C$3*T18 -> 2.633874 | Y18: =U18*$C$4 -> 0.0077958216 | Z18: =V18*$C$5 -> 0.011067282 | AA18: =IF(S18="TJ/m3", "kg CO2e/m3", "kg CO2e/kg") -> kg CO2e/kg | AB18: =SUM(X18:Z18)*IF(AND(F18="gramos",S18="TJ/m3")=TRUE(),1/(K18*1000000), IF(AND(F18="gramos",S18="TJ/kg")=TRUE(),1/(1000), IF(AND(F18="kilogramos",S18="TJ/m3")=TRUE(),1/(K18*1000), IF(AND(F18="toneladas",S18="TJ/m3")=TRUE(),1/K18, IF(AND(F18="toneladas",S18="TJ/kg")=TRUE(),1000, IF(AND(S18="TJ/m3",F18="litros")=TRUE(),1/1000, IF(AND(S18="TJ/kg",F18="litros")=TRUE(),K18/1000,1))))))) -> 2652.7371 | AC18: ="kgCO2e/"&F18 -> kgCO2e/toneladas | AD18: IPCC 2006 (vol2; chapter 2) , Table 2.4 | AE18: CNE BNE 2024 | AF18: -
B19: Carbón metalúrgico | C19: Carbón | D19: Carbón de coque | E19: Coking Coal | F19: kilogramos | G19: Sólido | H19: ='1.1 V2 CH2 T2.4'!$F$29 -> 94600 | I19: ='1.1 V2 CH2 T2.4'!$I$29 -> 10 | J19: ='1.1 V2 CH2 T2.4'!$L$29 -> 1.5 | M19: ='1.1 y 1.2CUADROA1 - BNE 2024'!D$26 -> 7000 | N19: ='1.1 y 1.2CUADROA1 - BNE 2024'!E$23 -> kCal/kg | O19: =IF(G19="Gaseoso", M19*$C$9, M19*$C$8) -> 6650 | P19: =N19 -> kCal/kg | Q19: No | R19: =O19*$C$6/$C$7*IF(Q19="Sí",K19*1000,1) -> 2.784222e-05 | S19: =IF(Q19="Sí","TJ/m3", IF(N19="kcal/m3", "TJ/m3","TJ/kg")) -> TJ/kg | T19: =H19*$R19 -> 2.633874 | U19: =I19*$R19 -> 0.0002784222 | V19: =J19*$R19 -> 4.176333e-05 | W19: =IF(S19="TJ/m3", "kg GEI/m3", "kg GEI/kg") -> kg GEI/kg | X19: =$C$3*T19 -> 2.633874 | Y19: =U19*$C$4 -> 0.0077958216 | Z19: =V19*$C$5 -> 0.011067282 | AA19: =IF(S19="TJ/m3", "kg CO2e/m3", "kg CO2e/kg") -> kg CO2e/kg | AB19: =SUM(X19:Z19)*IF(AND(F19="gramos",S19="TJ/m3")=TRUE(),1/(K19*1000000), IF(AND(F19="gramos",S19="TJ/kg")=TRUE(),1/(1000), IF(AND(F19="kilogramos",S19="TJ/m3")=TRUE(),1/(K19*1000), IF(AND(F19="toneladas",S19="TJ/m3")=TRUE(),1/K19, IF(AND(F19="toneladas",S19="TJ/kg")=TRUE(),1000, IF(AND(S19="TJ/m3",F19="litros")=TRUE(),1/1000, IF(AND(S19="TJ/kg",F19="litros")=TRUE(),K19/1000,1))))))) -> 2.6527371 | AC19: ="kgCO2e/"&F19 -> kgCO2e/kilogramos | AD19: IPCC 2006 (vol2; chapter 2) , Table 2.4 | AE19: CNE BNE 2024 | AF19: -
B20: Carbón metalúrgico | C20: Carbón | D20: Carbón de coque | E20: Coking Coal | F20: gramos | G20: Sólido | H20: ='1.1 V2 CH2 T2.4'!$F$29 -> 94600 | I20: ='1.1 V2 CH2 T2.4'!$I$29 -> 10 | J20: ='1.1 V2 CH2 T2.4'!$L$29 -> 1.5 | M20: ='1.1 y 1.2CUADROA1 - BNE 2024'!D$26 -> 7000 | N20: ='1.1 y 1.2CUADROA1 - BNE 2024'!E$23 -> kCal/kg | O20: =IF(G20="Gaseoso", M20*$C$9, M20*$C$8) -> 6650 | P20: =N20 -> kCal/kg | Q20: No | R20: =O20*$C$6/$C$7*IF(Q20="Sí",K20*1000,1) -> 2.784222e-05 | S20: =IF(Q20="Sí","TJ/m3", IF(N20="kcal/m3", "TJ/m3","TJ/kg")) -> TJ/kg | T20: =H20*$R20 -> 2.633874 | U20: =I20*$R20 -> 0.0002784222 | V20: =J20*$R20 -> 4.176333e-05 | W20: =IF(S20="TJ/m3", "kg GEI/m3", "kg GEI/kg") -> kg GEI/kg | X20: =$C$3*T20 -> 2.633874 | Y20: =U20*$C$4 -> 0.0077958216 | Z20: =V20*$C$5 -> 0.011067282 | AA20: =IF(S20="TJ/m3", "kg CO2e/m3", "kg CO2e/kg") -> kg CO2e/kg | AB20: =SUM(X20:Z20)*IF(AND(F20="gramos",S20="TJ/m3")=TRUE(),1/(K20*1000000), IF(AND(F20="gramos",S20="TJ/kg")=TRUE(),1/(1000), IF(AND(F20="kilogramos",S20="TJ/m3")=TRUE(),1/(K20*1000), IF(AND(F20="toneladas",S20="TJ/m3")=TRUE(),1/K20, IF(AND(F20="toneladas",S20="TJ/kg")=TRUE(),1000, IF(AND(S20="TJ/m3",F20="litros")=TRUE(),1/1000, IF(AND(S20="TJ/kg",F20="litros")=TRUE(),K20/1000,1))))))) -> 0.0026527371 | AC20: ="kgCO2e/"&F20 -> kgCO2e/gramos | AD20: IPCC 2006 (vol2; chapter 2) , Table 2.4 | AE20: CNE BNE 2024 | AF20: -
B21: Carbón térmico | C21: Carbón | D21: Otro carbón bituminoso | E21: Other Bituminous Coal | F21: toneladas | G21: Sólido | H21: ='1.1 V2 CH2 T2.4'!$F$30 -> 94600 | I21: ='1.1 V2 CH2 T2.4'!$I$30 -> 10 | J21: ='1.1 V2 CH2 T2.4'!$L$30 -> 1.5 | M21: ='1.1 y 1.2CUADROA1 - BNE 2024'!D$26 -> 7000 | N21: ='1.1 y 1.2CUADROA1 - BNE 2024'!E$23 -> kCal/kg | O21: =IF(G21="Gaseoso", M21*$C$9, M21*$C$8) -> 6650 | P21: =N21 -> kCal/kg | Q21: No | R21: =O21*$C$6/$C$7*IF(Q21="Sí",K21*1000,1) -> 2.784222e-05 | S21: =IF(Q21="Sí","TJ/m3", IF(N21="kcal/m3", "TJ/m3","TJ/kg")) -> TJ/kg | T21: =H21*$R21 -> 2.633874 | U21: =I21*$R21 -> 0.0002784222 | V21: =J21*$R21 -> 4.176333e-05 | W21: =IF(S21="TJ/m3", "kg GEI/m3", "kg GEI/kg") -> kg GEI/kg | X21: =$C$3*T21 -> 2.633874 | Y21: =U21*$C$4 -> 0.0077958216 | Z21: =V21*$C$5 -> 0.011067282 | AA21: =IF(S21="TJ/m3", "kg CO2e/m3", "kg CO2e/kg") -> kg CO2e/kg | AB21: =SUM(X21:Z21)*IF(AND(F21="gramos",S21="TJ/m3")=TRUE(),1/(K21*1000000), IF(AND(F21="gramos",S21="TJ/kg")=TRUE(),1/(1000), IF(AND(F21="kilogramos",S21="TJ/m3")=TRUE(),1/(K21*1000), IF(AND(F21="toneladas",S21="TJ/m3")=TRUE(),1/K21, IF(AND(F21="toneladas",S21="TJ/kg")=TRUE(),1000, IF(AND(S21="TJ/m3",F21="litros")=TRUE(),1/1000, IF(AND(S21="TJ/kg",F21="litros")=TRUE(),K21/1000,1))))))) -> 2652.7371 | AC21: ="kgCO2e/"&F21 -> kgCO2e/toneladas | AD21: IPCC 2006 (vol2; chapter 2) , Table 2.4 | AE21: CNE BNE 2024 | AF21: -
B22: Carbón térmico | C22: Carbón | D22: Otro carbón bituminoso | E22: Other Bituminous Coal | F22: kilogramos | G22: Sólido | H22: ='1.1 V2 CH2 T2.4'!$F$30 -> 94600 | I22: ='1.1 V2 CH2 T2.4'!$I$30 -> 10 | J22: ='1.1 V2 CH2 T2.4'!$L$30 -> 1.5 | M22: ='1.1 y 1.2CUADROA1 - BNE 2024'!D$26 -> 7000 | N22: ='1.1 y 1.2CUADROA1 - BNE 2024'!E$23 -> kCal/kg | O22: =IF(G22="Gaseoso", M22*$C$9, M22*$C$8) -> 6650 | P22: =N22 -> kCal/kg | Q22: No | R22: =O22*$C$6/$C$7*IF(Q22="Sí",K22*1000,1) -> 2.784222e-05 | S22: =IF(Q22="Sí","TJ/m3", IF(N22="kcal/m3", "TJ/m3","TJ/kg")) -> TJ/kg | T22: =H22*$R22 -> 2.633874 | U22: =I22*$R22 -> 0.0002784222 | V22: =J22*$R22 -> 4.176333e-05 | W22: =IF(S22="TJ/m3", "kg GEI/m3", "kg GEI/kg") -> kg GEI/kg | X22: =$C$3*T22 -> 2.633874 | Y22: =U22*$C$4 -> 0.0077958216 | Z22: =V22*$C$5 -> 0.011067282 | AA22: =IF(S22="TJ/m3", "kg CO2e/m3", "kg CO2e/kg") -> kg CO2e/kg | AB22: =SUM(X22:Z22)*IF(AND(F22="gramos",S22="TJ/m3")=TRUE(),1/(K22*1000000), IF(AND(F22="gramos",S22="TJ/kg")=TRUE(),1/(1000), IF(AND(F22="kilogramos",S22="TJ/m3")=TRUE(),1/(K22*1000), IF(AND(F22="toneladas",S22="TJ/m3")=TRUE(),1/K22, IF(AND(F22="toneladas",S22="TJ/kg")=TRUE(),1000, IF(AND(S22="TJ/m3",F22="litros")=TRUE(),1/1000, IF(AND(S22="TJ/kg",F22="litros")=TRUE(),K22/1000,1))))))) -> 2.6527371 | AC22: ="kgCO2e/"&F22 -> kgCO2e/kilogramos | AD22: IPCC 2006 (vol2; chapter 2) , Table 2.4 | AE22: CNE BNE 2024 | AF22: -
B23: Carbón térmico | C23: Carbón | D23: Otro carbón bituminoso | E23: Other Bituminous Coal | F23: gramos | G23: Sólido | H23: ='1.1 V2 CH2 T2.4'!$F$30 -> 94600 | I23: ='1.1 V2 CH2 T2.4'!$I$30 -> 10 | J23: ='1.1 V2 CH2 T2.4'!$L$30 -> 1.5 | M23: ='1.1 y 1.2CUADROA1 - BNE 2024'!D$26 -> 7000 | N23: ='1.1 y 1.2CUADROA1 - BNE 2024'!E$23 -> kCal/kg | O23: =IF(G23="Gaseoso", M23*$C$9, M23*$C$8) -> 6650 | P23: =N23 -> kCal/kg | Q23: No | R23: =O23*$C$6/$C$7*IF(Q23="Sí",K23*1000,1) -> 2.784222e-05 | S23: =IF(Q23="Sí","TJ/m3", IF(N23="kcal/m3", "TJ/m3","TJ/kg")) -> TJ/kg | T23: =H23*$R23 -> 2.633874 | U23: =I23*$R23 -> 0.0002784222 | V23: =J23*$R23 -> 4.176333e-05 | W23: =IF(S23="TJ/m3", "kg GEI/m3", "kg GEI/kg") -> kg GEI/kg | X23: =$C$3*T23 -> 2.633874 | Y23: =U23*$C$4 -> 0.0077958216 | Z23: =V23*$C$5 -> 0.011067282 | AA23: =IF(S23="TJ/m3", "kg CO2e/m3", "kg CO2e/kg") -> kg CO2e/kg | AB23: =SUM(X23:Z23)*IF(AND(F23="gramos",S23="TJ/m3")=TRUE(),1/(K23*1000000), IF(AND(F23="gramos",S23="TJ/kg")=TRUE(),1/(1000), IF(AND(F23="kilogramos",S23="TJ/m3")=TRUE(),1/(K23*1000), IF(AND(F23="toneladas",S23="TJ/m3")=TRUE(),1/K23, IF(AND(F23="toneladas",S23="TJ/kg")=TRUE(),1000, IF(AND(S23="TJ/m3",F23="litros")=TRUE(),1/1000, IF(AND(S23="TJ/kg",F23="litros")=TRUE(),K23/1000,1))))))) -> 0.0026527371 | AC23: ="kgCO2e/"&F23 -> kgCO2e/gramos | AD23: IPCC 2006 (vol2; chapter 2) , Table 2.4 | AE23: CNE BNE 2024 | AF23: -
B24: Gasolina | C24: Gasolina Motor | D24: Gasolina para motores | E24: Motor Gasoline | F24: metros cúbicos | G24: Líquido | H24: ='1.1 V2 CH2 T2.4'!$F$8 -> 69300 | I24: ='1.1 V2 CH2 T2.4'!$I$8 -> 10 | J24: ='1.1 V2 CH2 T2.4'!$L$8 -> 0.6 | K24: ='1.1 y 1.2CUADROA1 - BNE 2024'!$C$16 -> 0.73 | L24: t/m3 | M24: ='1.1 y 1.2CUADROA1 - BNE 2024'!D$16 -> 11200 | N24: ='1.1 y 1.2CUADROA1 - BNE 2024'!E$16 -> kCal/kg | O24: =IF(G24="Gaseoso", M24*$C$9, M24*$C$8) -> 10640 | P24: =N24 -> kCal/kg | Q24: Sí | R24: =O24*$C$6/$C$7*IF(Q24="Sí",K24*1000,1) -> 0.032519713 | S24: =IF(Q24="Sí","TJ/m3", IF(N24="kcal/m3", "TJ/m3","TJ/kg")) -> TJ/m3 | T24: =H24*$R24 -> 2253.6161 | U24: =I24*$R24 -> 0.32519713 | V24: =J24*$R24 -> 0.019511828 | W24: =IF(S24="TJ/m3", "kg GEI/m3", "kg GEI/kg") -> kg GEI/m3 | X24: =$C$3*T24 -> 2253.6161 | Y24: =U24*$C$4 -> 9.1055196 | Z24: =V24*$C$5 -> 5.1706344 | AA24: =IF(S24="TJ/m3", "kg CO2e/m3", "kg CO2e/kg") -> kg CO2e/m3 | AB24: =SUM(X24:Z24)*IF(AND(F24="gramos",S24="TJ/m3")=TRUE(),1/(K24*1000000), IF(AND(F24="gramos",S24="TJ/kg")=TRUE(),1/(1000), IF(AND(F24="kilogramos",S24="TJ/m3")=TRUE(),1/(K24*1000), IF(AND(F24="toneladas",S24="TJ/m3")=TRUE(),1/K24, IF(AND(F24="toneladas",S24="TJ/kg")=TRUE(),1000, IF(AND(S24="TJ/m3",F24="litros")=TRUE(),1/1000, IF(AND(S24="TJ/kg",F24="litros")=TRUE(),K24/1000,1))))))) -> 2267.8923 | AC24: ="kgCO2e/"&F24 -> kgCO2e/metros cúbicos | AD24: IPCC 2006 (vol2; chapter 2) , Table 2.4 | AE24: CNE BNE 2024 | AF24: -
B25: Gasolina | C25: Gasolina Motor | D25: Gasolina para motores | E25: Motor Gasoline | F25: litros | G25: Líquido | H25: ='1.1 V2 CH2 T2.4'!$F$8 -> 69300 | I25: ='1.1 V2 CH2 T2.4'!$I$8 -> 10 | J25: ='1.1 V2 CH2 T2.4'!$L$8 -> 0.6 | K25: ='1.1 y 1.2CUADROA1 - BNE 2024'!$C$16 -> 0.73 | L25: t/m3 | M25: ='1.1 y 1.2CUADROA1 - BNE 2024'!D$16 -> 11200 | N25: ='1.1 y 1.2CUADROA1 - BNE 2024'!E$16 -> kCal/kg | O25: =IF(G25="Gaseoso", M25*$C$9, M25*$C$8) -> 10640 | P25: =N25 -> kCal/kg | Q25: Sí | R25: =O25*$C$6/$C$7*IF(Q25="Sí",K25*1000,1) -> 0.032519713 | S25: =IF(Q25="Sí","TJ/m3", IF(N25="kcal/m3", "TJ/m3","TJ/kg")) -> TJ/m3 | T25: =H25*$R25 -> 2253.6161 | U25: =I25*$R25 -> 0.32519713 | V25: =J25*$R25 -> 0.019511828 | W25: =IF(S25="TJ/m3", "kg GEI/m3", "kg GEI/kg") -> kg GEI/m3 | X25: =$C$3*T25 -> 2253.6161 | Y25: =U25*$C$4 -> 9.1055196 | Z25: =V25*$C$5 -> 5.1706344 | AA25: =IF(S25="TJ/m3", "kg CO2e/m3", "kg CO2e/kg") -> kg CO2e/m3 | AB25: =SUM(X25:Z25)*IF(AND(F25="gramos",S25="TJ/m3")=TRUE(),1/(K25*1000000), IF(AND(F25="gramos",S25="TJ/kg")=TRUE(),1/(1000), IF(AND(F25="kilogramos",S25="TJ/m3")=TRUE(),1/(K25*1000), IF(AND(F25="toneladas",S25="TJ/m3")=TRUE(),1/K25, IF(AND(F25="toneladas",S25="TJ/kg")=TRUE(),1000, IF(AND(S25="TJ/m3",F25="litros")=TRUE(),1/1000, IF(AND(S25="TJ/kg",F25="litros")=TRUE(),K25/1000,1))))))) -> 2.2678923 | AC25: ="kgCO2e/"&F25 -> kgCO2e/litros | AD25: IPCC 2006 (vol2; chapter 2) , Table 2.4 | AE25: CNE BNE 2024 | AF25: -
B26: Gas de alto horno | C26: - | D26: Gas de alto horno | E26: Blast Furnace Gas | F26: toneladas | G26: Gaseoso | H26: ='1.1 V2 CH2 T2.4'!$F$41 -> 260000 | I26: ='1.1 V2 CH2 T2.4'!$I$41 -> 5 | J26: ='1.1 V2 CH2 T2.4'!$L$41 -> 0.1 | M26: =2.47*1000/C$6 -> 589.94936 | N26: kcal/kg | O26: =IF(G26="Gaseoso", M26*$C$9, M26*$C$8) -> 530.95443 | P26: =N26 -> kcal/kg | Q26: No | R26: =O26*$C$6/$C$7*IF(Q26="Sí",K26*1000,1) -> 2.223e-06 | S26: =IF(Q26="Sí","TJ/m3", IF(N26="kcal/m3", "TJ/m3","TJ/kg")) -> TJ/kg | T26: =H26*$R26 -> 0.57798 | U26: =I26*$R26 -> 1.1115e-05 | V26: =J26*$R26 -> 2.223e-07 | W26: =IF(S26="TJ/m3", "kg GEI/m3", "kg GEI/kg") -> kg GEI/kg | X26: =$C$3*T26 -> 0.57798 | Y26: =U26*$C$4 -> 0.00031122 | Z26: =V26*$C$5 -> 5.89095e-05 | AA26: =IF(S26="TJ/m3", "kg CO2e/m3", "kg CO2e/kg") -> kg CO2e/kg | AB26: =SUM(X26:Z26)*IF(AND(F26="gramos",S26="TJ/m3")=TRUE(),1/(K26*1000000), IF(AND(F26="gramos",S26="TJ/kg")=TRUE(),1/(1000), IF(AND(F26="kilogramos",S26="TJ/m3")=TRUE(),1/(K26*1000), IF(AND(F26="toneladas",S26="TJ/m3")=TRUE(),1/K26, IF(AND(F26="toneladas",S26="TJ/kg")=TRUE(),1000, IF(AND(S26="TJ/m3",F26="litros")=TRUE(),1/1000, IF(AND(S26="TJ/kg",F26="litros")=TRUE(),K26/1000,1))))))) -> 578.35013 | AC26: ="kgCO2e/"&F26 -> kgCO2e/toneladas | AD26: IPCC 2006 (vol2; chapter 2) , Table 2.4 | AE26: CNE BNE 2024 | AF26: IPCC 2006 (vol2; chapter 1) , Table 1.2
B27: Gas de alto horno | C27: - | D27: Gas de alto horno | E27: Blast Furnace Gas | F27: kilogramos | G27: Gaseoso | H27: ='1.1 V2 CH2 T2.4'!$F$41 -> 260000 | I27: ='1.1 V2 CH2 T2.4'!$I$41 -> 5 | J27: ='1.1 V2 CH2 T2.4'!$L$41 -> 0.1 | M27: =2.47*1000/C$6 -> 589.94936 | N27: kcal/kg | O27: =IF(G27="Gaseoso", M27*$C$9, M27*$C$8) -> 530.95443 | P27: =N27 -> kcal/kg | Q27: No | R27: =O27*$C$6/$C$7*IF(Q27="Sí",K27*1000,1) -> 2.223e-06 | S27: =IF(Q27="Sí","TJ/m3", IF(N27="kcal/m3", "TJ/m3","TJ/kg")) -> TJ/kg | T27: =H27*$R27 -> 0.57798 | U27: =I27*$R27 -> 1.1115e-05 | V27: =J27*$R27 -> 2.223e-07 | W27: =IF(S27="TJ/m3", "kg GEI/m3", "kg GEI/kg") -> kg GEI/kg | X27: =$C$3*T27 -> 0.57798 | Y27: =U27*$C$4 -> 0.00031122 | Z27: =V27*$C$5 -> 5.89095e-05 | AA27: =IF(S27="TJ/m3", "kg CO2e/m3", "kg CO2e/kg") -> kg CO2e/kg | AB27: =SUM(X27:Z27)*IF(AND(F27="gramos",S27="TJ/m3")=TRUE(),1/(K27*1000000), IF(AND(F27="gramos",S27="TJ/kg")=TRUE(),1/(1000), IF(AND(F27="kilogramos",S27="TJ/m3")=TRUE(),1/(K27*1000), IF(AND(F27="toneladas",S27="TJ/m3")=TRUE(),1/K27, IF(AND(F27="toneladas",S27="TJ/kg")=TRUE(),1000, IF(AND(S27="TJ/m3",F27="litros")=TRUE(),1/1000, IF(AND(S27="TJ/kg",F27="litros")=TRUE(),K27/1000,1))))))) -> 0.57835013 | AC27: ="kgCO2e/"&F27 -> kgCO2e/kilogramos | AD27: IPCC 2006 (vol2; chapter 2) , Table 2.4 | AE27: CNE BNE 2024 | AF27: IPCC 2006 (vol2; chapter 1) , Table 1.2
